Traceback (most recent call last):
  File "main.py", line 21, in <module>
    browser = Firefox(options=opts)
  File "/opt/virtualenvs/python3/lib/python3.8/site-packages/selenium/webdriver/firefox/webdriver.py", line 170, in __init__
    RemoteWebDriver.__init__(
  File "/opt/virtualenvs/python3/lib/python3.8/site-packages/selenium/webdriver/remote/webdriver.py", line 157, in __init__
    self.start_session(capabilities, browser_profile)
  File "/opt/virtualenvs/python3/lib/python3.8/site-packages/selenium/webdriver/remote/webdriver.py", line 252, in start_session
    response = self.execute(Command.NEW_SESSION, parameters)
  File "/opt/virtualenvs/python3/lib/python3.8/site-packages/selenium/webdriver/remote/webdriver.py", line 321, in execute
    self.error_handler.check_response(response)
  File "/opt/virtualenvs/python3/lib/python3.8/site-packages/selenium/webdriver/remote/errorhandler.py", line 242, in check_response
    raise exception_class(message, screen, stacktrace)
selenium.common.exceptions.TimeoutException: Message: Connection refused (os error 111)
