Exception in thread Thread-1:
Traceback (most recent call last):
  File "/usr/lib/python3.8/threading.py", line 932, in _bootstrap_inner
    self.run()
  File "/usr/lib/python3.8/threading.py", line 870, in run
    self._target(*self._args, **self._kwargs)
  File "/home/runner/Elegant-Browser-Automation-with-Python-and-Selenium/keep_alive.py", line 11, in run
    app.run(host='0.0.0.0',port=8080)
  File "/opt/virtualenvs/python3/lib/python3.8/site-packages/flask/app.py", line 922, in run
    run_simple(t.cast(str, host), port, self, **options)
  File "/opt/virtualenvs/python3/lib/python3.8/site-packages/werkzeug/serving.py", line 1008, in run_simple
    inner()
  File "/opt/virtualenvs/python3/lib/python3.8/site-packages/werkzeug/serving.py", line 948, in inner
    srv = make_server(
  File "/opt/virtualenvs/python3/lib/python3.8/site-packages/werkzeug/serving.py", line 780, in make_server
    return ThreadedWSGIServer(
  File "/opt/virtualenvs/python3/lib/python3.8/site-packages/werkzeug/serving.py", line 686, in __init__
    super().__init__(server_address, handler)  # type: ignore
  File "/usr/lib/python3.8/socketserver.py", line 452, in __init__
    self.server_bind()
  File "/usr/lib/python3.8/http/server.py", line 138, in server_bind
    socketserver.TCPServer.server_bind(self)
  File "/usr/lib/python3.8/socketserver.py", line 466, in server_bind
    self.socket.bind(self.server_address)
OSError: [Errno 98] Address already in use
Traceback (most recent call last):
  File "main.py", line 21, in <module>
    browser = Firefox(options=opts)
  File "/opt/virtualenvs/python3/lib/python3.8/site-packages/selenium/webdriver/firefox/webdriver.py", line 170, in __init__
    RemoteWebDriver.__init__(
  File "/opt/virtualenvs/python3/lib/python3.8/site-packages/selenium/webdriver/remote/webdriver.py", line 157, in __init__
    self.start_session(capabilities, browser_profile)
  File "/opt/virtualenvs/python3/lib/python3.8/site-packages/selenium/webdriver/remote/webdriver.py", line 252, in start_session
    response = self.execute(Command.NEW_SESSION, parameters)
  File "/opt/virtualenvs/python3/lib/python3.8/site-packages/selenium/webdriver/remote/webdriver.py", line 321, in execute
    self.error_handler.check_response(response)
  File "/opt/virtualenvs/python3/lib/python3.8/site-packages/selenium/webdriver/remote/errorhandler.py", line 242, in check_response
    raise exception_class(message, screen, stacktrace)
selenium.common.exceptions.TimeoutException: Message: Connection refused (os error 111)